2024-01-30 18:10:09,706 - instabot version: 0.117.0 (bot) - INFO - Instabot version: 0.117.0 Started
2024-01-30 18:10:09,706 - instabot version: 0.117.0 (bot) - DEBUG - Bot imported from C:\python 3.10\lib\site-packages\instabot\bot\bot.py
2024-01-30 18:10:09,724 - instabot version: 0.117.0 (api_login) - INFO - Not yet logged in starting: PRE-LOGIN FLOW!
2024-01-30 18:10:09,749 - instabot version: 0.117.0 (api) - WARNING - HTTPSConnectionPool(host='i.instagram.com', port=443): Max retries exceeded with url: /api/v1/accounts/get_prefill_candidates/ (Caused by NameResolutionError("<urllib3.connection.HTTPSConnection object at 0x000001D704F4DE70>: Failed to resolve 'i.instagram.com' ([Errno 11001] getaddrinfo failed)"))
2024-01-30 18:10:09,752 - instabot version: 0.117.0 (api) - WARNING - HTTPSConnectionPool(host='i.instagram.com', port=443): Max retries exceeded with url: /api/v1/qe/sync/ (Caused by NameResolutionError("<urllib3.connection.HTTPSConnection object at 0x000001D704F4E2C0>: Failed to resolve 'i.instagram.com' ([Errno 11001] getaddrinfo failed)"))
2024-01-30 18:10:09,755 - instabot version: 0.117.0 (api) - WARNING - HTTPSConnectionPool(host='i.instagram.com', port=443): Max retries exceeded with url: /api/v1/launcher/sync/ (Caused by NameResolutionError("<urllib3.connection.HTTPSConnection object at 0x000001D704F4E620>: Failed to resolve 'i.instagram.com' ([Errno 11001] getaddrinfo failed)"))
2024-01-30 18:10:09,758 - instabot version: 0.117.0 (api) - WARNING - HTTPSConnectionPool(host='i.instagram.com', port=443): Max retries exceeded with url: /api/v1/accounts/contact_point_prefill/ (Caused by NameResolutionError("<urllib3.connection.HTTPSConnection object at 0x000001D704F4E3E0>: Failed to resolve 'i.instagram.com' ([Errno 11001] getaddrinfo failed)"))
